вторник, 19 августа 2025 г. 21:49:36 (+05): ===== Запуск run_monthly_tasks.sh =====
вторник, 19 августа 2025 г. 21:49:36 (+05): ===== Начало ежемесячного обновления Homebrew =====
вторник, 19 августа 2025 г. 21:49:36 (+05): Обновление индекса Homebrew…
==> Updating Homebrew...
Already up-to-date.
вторник, 19 августа 2025 г. 21:49:41 (+05): Обновление formulae и casks…
вторник, 19 августа 2025 г. 21:49:43 (+05): Очистка старых версий и кэша…
вторник, 19 августа 2025 г. 21:49:47 (+05): Ежемесячное обновление Homebrew завершено.
вторник, 19 августа 2025 г. 21:49:49 (+05): Brewfile обновлён.
вторник, 19 августа 2025 г. 21:49:49 (+05): Запуск Telegram keep-alive…
error: externally-managed-environment

× This environment is externally managed
╰─> To install Python packages system-wide, try brew install
    xyz, where xyz is the package you are trying to
    install.
    
    If you wish to install a Python library that isn't in Homebrew,
    use a virtual environment:
    
    python3 -m venv path/to/venv
    source path/to/venv/bin/activate
    python3 -m pip install xyz
    
    If you wish to install a Python application that isn't in Homebrew,
    it may be easiest to use 'pipx install xyz', which will manage a
    virtual environment for you. You can install pipx with
    
    brew install pipx
    
    You may restore the old behavior of pip by passing
    the '--break-system-packages' flag to pip, or by adding
    'break-system-packages = true' to your pip.conf file. The latter
    will permanently disable this error.
    
    If you disable this error, we STRONGLY recommend that you additionally
    pass the '--user' flag to pip, or set 'user = true' in your pip.conf
    file. Failure to do this can result in a broken Homebrew installation.
    
    Read more about this behavior here: <https://peps.python.org/pep-0668/>

note: If you believe this is a mistake, please contact your Python installation or OS distribution provider. You can override this, at the risk of breaking your Python installation or OS, by passing --break-system-packages.
hint: See PEP 668 for the detailed specification.
Traceback (most recent call last):
  File "<stdin>", line 3, in <module>
ModuleNotFoundError: No module named 'telethon'

During handling of the above exception, another exception occurred:

Traceback (most recent call last):
  File "<stdin>", line 5, in <module>
  File "/opt/homebrew/Cellar/python@3.13/3.13.7/Frameworks/Python.framework/Versions/3.13/lib/python3.13/subprocess.py", line 419, in check_call
    raise CalledProcessError(retcode, cmd)
subprocess.CalledProcessError: Command '['/opt/homebrew/opt/python@3.13/bin/python3.13', '-m', 'pip', 'install', '--quiet', '--user', 'telethon']' returned non-zero exit status 1.
Traceback (most recent call last):
  File "/Users/khurshidddbek/dotfiles/scripts/telegram/extract_public_chats.py", line 14, in <module>
    from telethon import TelegramClient
ModuleNotFoundError: No module named 'telethon'
Traceback (most recent call last):
  File "/Users/khurshidddbek/dotfiles/scripts/telegram/send_keepalive.py", line 12, in <module>
    from telethon import TelegramClient
ModuleNotFoundError: No module named 'telethon'
вторник, 19 августа 2025 г. 21:49:50 (+05): Telegram keep-alive завершился с ошибкой code=1
вторник, 19 августа 2025 г. 21:49:50 (+05): Обнаружены изменения. Начинаем обработку...
вторник, 19 августа 2025 г. 21:49:50 (+05): Неизвестный файл или папка: scheduled_tasks.log. Пропускаем.
